Workbook
Name _: #REF!
Name ____CSP1: #REF!
Name ____MSP1: #REF!
Name ___CSP1: #REF!
Name ___MSP1: #REF!
Name __CSP1: #REF!
Name __MSP1: #REF!
Name __US1: #REF!
Name _1.05gb_nonplug_drive: [1]Supplement2!#REF!
Name _1.05gb_plug_drive: [1]Supplement2!#REF!
Name _15A: [2]금액내역서!$D$3:$D$10
Name _2.1gb_fastwide_plug_drive: [1]Supplement2!#REF!
Name _2.1gb_nonplug_drive: [1]Supplement2!#REF!
Name _2.1gb_plug_drive: [1]Supplement2!#REF!
Name _32mb_70nsmemory: [1]Supplement2!#REF!
Name _4.3gb_fastwide_plug_drive: [1]Supplement2!#REF!
Name _4.3gb_nonplug_drive: [1]Supplement2!#REF!
Name _535mb_nonplug_drive: [1]Supplement2!#REF!
Name _8mb_70nsmemory: [1]Supplement2!#REF!
Name _CSP1: #REF!
Name _MSP1: #REF!
Name _SMART_SCSIarray: [1]Supplement2!#REF!
Name _US1: #REF!
Name ADSF: [3]xxxxxx!$A$1:$F$33
Name ARROW: #REF!
Name CDC: #REF!
Name CDR: #REF!
Name Chart_1: "Chart 1"
Name CiscoSP1: #REF!
Name CM: '[4]원가분석(Cisco)'!#REF!
Name concordSP1: #REF!
Name cost: #REF!
Name CSDC: '[4]원가분석(Cisco)'!$L$2
Name CSSP: #REF!
Name d: #REF!
Name DART: #REF!
Name DATE: #REF!
Name DazzlerPCI_array: [1]Supplement2!#REF!
Name DC: #REF!
Name DCRATE: '[6]PassPort-60%'!#REF!
Name DC율: #REF!
Name DEL: #REF!
Name dkdkdkd: #REF!
Name GM: #REF!
Name HTML_Control_2_1: {"'건축내역'!$A$1:$L$413"}
Name HTML_Control_3_1: {"'건축내역'!$A$1:$L$413"}
Name HTML_Control_4_1: {"'건축내역'!$A$1:$L$413"}
Name HTML_Control_5_1: {"'건축내역'!$A$1:$L$413"}
Name IM: '[4]원가분석(Cisco)'!#REF!
Name INV: #REF!
Name LDC: #REF!
Name minus: #REF!
Name mot: #REF!
Name NO: #REF!
Name NortelDC: [7]원가보고!#REF!
Name NortelSF: [7]원가보고!#REF!
Name NortelSP1: #REF!
Name Nortel제안가: [7]원가보고!#REF!
Name PDC: #REF!
Name PL_storage: [1]Supplement2!#REF!

Sheet 견적서
A1: 견 적 서
A5: 수 신 : | B5: KDB산업은행 | C5: 상 호 | E5: ㈜비에이앤티
A6: 참 조 : | C6: 대표이사 | E6: 임 종 훈
A7: 견적번호 : | B7: 2024-ICT02-1112-001 | C7: 등록번호 | E7: 549-88-00478 | F7: 전 화 | G7: 02-560-4690~2
A8: 견적일자 : | B8: 45608 | C8: 주 소 | E8: 서울시 송파구 충민로 10, 가든파이브툴동 S30-1호
A10: 합 계 | B10: =(""&" " & "일금 "&NUMBERSTRING(F33,1)&"원정"&" (￦")&TEXT(F33,"#,##0)"&" (VAT포함)") -> 일금 이십구억삼천팔만원정 (￦2,930,080,000) (VAT포함)
A12: 품명 | B12: 상세내역 | C12: 수량 | D12: 단위 | E12: 공급단가 | F12: 공급가 합계 | G12: 비고
A15: 2024년 통합유지보수 (네트워크) | B15: 통합유지보수 관련 기술지원료 | C15: 1 | D15: 식 | E15: =상세내역!J81 -> 943600000 | F15: =C15*E15 -> 943600000 | G15: ** 세부내역 참조
B16: - 본점 및 전산센터 월 1회 정기점검, 지점 분기 1회 정기점검, 기타 원격점검
B17: - 24 x 7 기술지원 및 장애시 RMA 지원
B18: - 장애접수 후 3시간이내 현장도착 및 6시간 이내 복구 (수도권 이외는 4시간 이내)
B19: - 장애처리 후 5일 이내 장애보고서 제출 (재발방지대책 포함)
A20: 2025년 통합유지보수 (네트워크) | B20: 통합유지보수 관련 기술지원료 | C20: 1 | D20: 식 | E20: =상세내역!K81 -> 968250000 | F20: =C20*E20 -> 968250000
B21: - 본점 및 전산센터 월 1회 정기점검, 지점 분기 1회 정기점검, 기타 원격점검
B22: - 24 x 7 기술지원 및 장애시 RMA 지원
B23: - 장애접수 후 3시간이내 현장도착 및 6시간 이내 복구 (수도권 이외는 4시간 이내)
B24: - 장애처리 후 5일 이내 장애보고서 제출 (재발방지대책 포함)
A25: 2026년 통합유지보수 (네트워크) | B25: 통합유지보수 관련 기술지원료 | C25: 1 | D25: 식 | E25: =상세내역!L81 -> 969720000 | F25: =C25*E25 -> 969720000
B26: - 본점 및 전산센터 월 1회 정기점검, 지점 분기 1회 정기점검, 기타 원격점검
B27: - 24 x 7 기술지원 및 장애시 RMA 지원
B28: - 장애접수 후 3시간이내 현장도착 및 6시간 이내 복구 (수도권 이외는 4시간 이내)
B29: - 장애처리 후 5일 이내 장애보고서 제출 (재발방지대책 포함)
A30: 통합. 네트워크(공사) | B30: RACK 및 장비 이전설치, 운송비, 인건비 포함 (5회/년) | C30: 15 | D30: 건 | E30: =상세내역!I78 -> 1100000 | F30: =C30*E30 -> 16500000
B31: 통신케이블공, 차량, 잡자재 및 유류비 (10회/년) | C31: 30 | D31: 건 | E31: =상세내역!I79 -> 800000 | F31: =C31*E31 -> 24000000
B32: 무선AP 케이블(25M 기준), 내선전공, 통신케이블공, 통신설비공 및 보통인부 (5회/년) | C32: 15 | D32: 건 | E32: =상세내역!I80 -> 534000 | F32: =C32*E32 -> 8010000
A33: 합 계 (VAT 포함) | F33: =SUM(F15:F32) -> 2930080000 | G33: 만원이하절삭
A36: Remark : | C36: 견적담당:
A37: 1. 견적유효기간 : 견적일로부터 60일 | C37: ㈜비에이앤티 ICT사업부 이상은 이사
A38: 2. 장비납기 : 해당없음 | C38: Office : 02-560-4690~2, FAX : 02-560-4689
A39: 3. 계약기간 : 2024.01.01 ~ 2026.12.31 (36개월) | C39: Mobile : 010-6282-6353, e-mail : selee@bantech.co.kr
A40: 4. 대금지급조건 : 귀사 지급 조건
A41: 5. 지원조건 : 별도협의

Sheet 상세내역
A2: O (전체) 입찰견적서
A4: No. | B4: 장비구분 | C4: 구분 | D4: 제조사 | E4: 제품명 | F4: 수량 | G4: 유지보수 기간 | H4: 총 개월수 | I4: 비용 (월) | J4: 합계 (2024년) | K4: 합계 (2025년) | L4: 합계 (2026년) | M4: 총합 | N4: 비고 (신규/제외 사유)
A5: 1 | B5: 유선 | C5: GateKeeper | D5: CISCO | E5: CISCO3945-V/K9 | F5: 2 | G5: 24.1~26.12 | H5: 36 | I5: 80000 | J5: =I5*12 -> 960000 | K5: =I5*12 -> 960000 | L5: =I5*12 -> 960000 | M5: =SUM(J5:L5) -> 2880000
A6: 2 | B6: 유선 | C6: L2 스위치 | D6: CISCO | E6: C2950G | F6: 2 | G6: 24.1~26.12 | H6: 36 | I6: 10000 | J6: =I6*12 -> 120000 | K6: =I6*12 -> 120000 | L6: =I6*12 -> 120000 | M6: =SUM(J6:L6) -> 360000
A7: 3 | B7: 유선 | C7: L2 스위치 | D7: CISCO | E7: C2960CG-8TC-L | F7: 87 | G7: 24.1~26.12 | H7: 36 | I7: 260000 | J7: =I7*12 -> 3120000 | K7: =I7*12 -> 3120000 | L7: =I7*12 -> 3120000 | M7: =SUM(J7:L7) -> 9360000
A8: 4 | B8: 유선 | C8: L2 스위치 | D8: CISCO | E8: C2960G | F8: 1 | G8: 24.1~26.12 | H8: 36 | I8: 10000 | J8: =I8*12 -> 120000 | K8: =I8*12 -> 120000 | L8: =I8*12 -> 120000 | M8: =SUM(J8:L8) -> 360000
A9: 5 | B9: 유선 | C9: L2 스위치 | D9: CISCO | E9: C2960X-24TS-L | F9: 35 | G9: 24.1~26.12 | H9: 36 | I9: 110000 | J9: =I9*12 -> 1320000 | K9: =I9*12 -> 1320000 | L9: =I9*12 -> 1320000 | M9: =SUM(J9:L9) -> 3960000
A10: 6 | B10: 유선 | C10: L2 스위치 | D10: CISCO | E10: C2960X-48TS-L | F10: 327 | G10: 24.1~26.12 | H10: 36 | I10: 1250000 | J10: =I10*12 -> 15000000 | K10: 12000000 | L10: 12000000 | M10: =SUM(J10:L10) -> 39000000 | N10: 25년부터 제외 (83대)
A11: 7 | B11: 유선 | C11: L2 스위치 | D11: CISCO | E11: C3048-BA-L3 | F11: 14 | G11: 24.1~26.12 | H11: 36 | I11: 170000 | J11: =I11*12 -> 2040000 | K11: =I11*12 -> 2040000 | L11: =I11*12 -> 2040000 | M11: =SUM(J11:L11) -> 6120000
A12: 8 | B12: 유선 | C12: L2 스위치 | D12: CISCO | E12: C3524P-10GX | F12: 26 | G12: 24.1~26.12 | H12: 36 | I12: 260000 | J12: =I12*12 -> 3120000 | K12: =I12*12 -> 3120000 | L12: =I12*12 -> 3120000 | M12: =SUM(J12:L12) -> 9360000
A13: 9 | B13: 유선 | C13: L2 스위치 | D13: CISCO | E13: C3548P-10GX | F13: 16 | G13: 24.1~26.12 | H13: 36 | I13: 160000 | J13: =I13*12 -> 1920000 | K13: =I13*12 -> 1920000 | L13: =I13*12 -> 1920000 | M13: =SUM(J13:L13) -> 5760000
A14: 10 | B14: 유선 | C14: L2 스위치 | D14: CISCO | E14: C3650-24TS-S | F14: 25 | G14: 24.1~26.12 | H14: 36 | I14: 150000 | J14: =I14*12 -> 1800000 | K14: =I14*12 -> 1800000 | L14: =I14*12 -> 1800000 | M14: =SUM(J14:L14) -> 5400000
A15: 11 | B15: 유선 | C15: L2 스위치 | D15: CISCO | E15: C3750 | F15: 0 | G15: 24.1~26.12 | H15: 12 | I15: 20000 | J15: =I15*12 -> 240000 | M15: =SUM(J15:L15) -> 240000 | N15: 25년부터 제외 (4대)
A16: 12 | B16: 유선 | C16: L2 스위치 | D16: CISCO | E16: C9407R | F16: 21 | G16: 24.1~26.12 | H16: 36 | I16: 4160000 | J16: =I16*12 -> 49920000 | K16: =I16*12 -> 49920000 | L16: =I16*12 -> 49920000 | M16: =SUM(J16:L16) -> 149760000
A17: 13 | B17: 유선 | C17: L2 스위치 | D17: CISCO (신규) | E17: N9K-C93180YC-FX | F17: 8 | G17: 24.2~26.12 | H17: 35 | I17: 160000 | J17: =I17*11 -> 1760000 | K17: =I17*12 -> 1920000 | L17: =I17*12 -> 1920000 | M17: =SUM(J17:L17) -> 5600000
A18: 14 | B18: 유선 | C18: L2 스위치 | D18: DELL EMC | E18: S3048-ON | F18: 2 | G18: 24.1~26.12 | H18: 36 | I18: 10000 | J18: =I18*12 -> 120000 | K18: =I18*12 -> 120000 | L18: =I18*12 -> 120000 | M18: =SUM(J18:L18) -> 360000
A19: 15 | B19: 유선 | C19: L2 스위치 | D19: DELL EMC (신규) | E19: S4128F-ON | F19: 2 | G19: 24.2~26.12 | H19: 35 | I19: 120000 | J19: =I19*11 -> 1320000 | K19: =I19*12 -> 1440000 | L19: =I19*12 -> 1440000 | M19: =SUM(J19:L19) -> 4200000
A20: 16 | B20: 유선 | C20: L2 스위치 | D20: DELL EMC (신규) | E20: S4148F-ON | F20: 2 | G20: 24.3~26.12 | H20: 34 | I20: 120000 | J20: =I20*10 -> 1200000 | K20: =I20*12 -> 1440000 | L20: =I20*12 -> 1440000 | M20: =SUM(J20:L20) -> 4080000
A21: 17 | B21: 유선 | C21: L2 스위치 | D21: DELL EMC (신규) | E21: S3048-ON | F21: 1 | G21: 24.3~26.12 | H21: 34 | I21: 60000 | J21: =I21*10 -> 600000 | K21: =I21*12 -> 720000 | L21: =I21*12 -> 720000 | M21: =SUM(J21:L21) -> 2040000
A22: 18 | B22: 유선 | C22: L3 스위치 | D22: CISCO | E22: C3524P-10GX | F22: 2 | G22: 24.1~26.12 | H22: 36 | I22: 20000 | J22: =I22*12 -> 240000 | K22: =I22*12 -> 240000 | L22: =I22*12 -> 240000 | M22: =SUM(J22:L22) -> 720000
A23: 19 | B23: 유선 | C23: L3 스위치 | D23: CISCO | E23: C3524-X-SPL3 | F23: 4 | G23: 24.1~26.12 | H23: 36 | I23: 50000 | J23: =I23*12 -> 600000 | K23: =I23*12 -> 600000 | L23: =I23*12 -> 600000 | M23: =SUM(J23:L23) -> 1800000
A24: 20 | B24: 유선 | C24: L3 스위치 | D24: CISCO | E24: C3548P-10GX | F24: 11 | G24: 24.1~26.12 | H24: 36 | I24: 110000 | J24: =I24*12 -> 1320000 | K24: =I24*12 -> 1320000 | L24: =I24*12 -> 1320000 | M24: =SUM(J24:L24) -> 3960000
A25: 21 | B25: 유선 | C25: L3 스위치 | D25: CISCO | E25: C7706-B26S2E-R | F25: 36 | G25: 24.1~26.12 | H25: 36 | I25: 22100000 | J25: =I25*12 -> 265200000 | K25: =I25*12 -> 265200000 | L25: =I25*12 -> 265200000 | M25: =SUM(J25:L25) -> 795600000
A26: 22 | B26: 유선 | C26: L3 스위치 | D26: CISCO | E26: C7710-B26S2E-R | F26: 6 | G26: 24.1~26.12 | H26: 36 | I26: 6150000 | J26: =I26*12 -> 73800000 | K26: =I26*12 -> 73800000 | L26: =I26*12 -> 73800000 | M26: =SUM(J26:L26) -> 221400000
A27: 23 | B27: 유선 | C27: L3 스위치 | D27: CISCO | E27: C9300-24T-A | F27: 2 | G27: 24.1~26.12 | H27: 36 | I27: 50000 | J27: =I27*12 -> 600000 | K27: =I27*12 -> 600000 | L27: =I27*12 -> 600000 | M27: =SUM(J27:L27) -> 1800000
A28: 24 | B28: 유선 | C28: L3 스위치 | D28: CISCO | E28: C9606R | F28: 2 | G28: 24.1~26.12 | H28: 36 | I28: 970000 | J28: =I28*12 -> 11640000 | K28: =I28*12 -> 11640000 | L28: =I28*12 -> 11640000 | M28: =SUM(J28:L28) -> 34920000
A29: 25 | B29: 유선 | C29: L3 스위치 | D29: CISCO | E29: Catalyst4507R | F29: 1 | G29: 24.1~26.12 | H29: 36 | I29: 120000 | J29: =I29*12 -> 1440000 | K29: =I29*12 -> 1440000 | L29: =I29*12 -> 1440000 | M29: =SUM(J29:L29) -> 4320000
A30: 26 | B30: 유선 | C30: L3 스위치 | D30: CISCO | E30: N3K-3548P-10GX | F30: 4 | G30: 24.1~26.12 | H30: 36 | I30: 40000 | J30: =I30*12 -> 480000 | K30: =I30*12 -> 480000 | L30: =I30*12 -> 480000 | M30: =SUM(J30:L30) -> 1440000
A31: 27 | B31: 유선 | C31: L3 스위치 | D31: CISCO | E31: N9K-9348GC-FXP | F31: 2 | G31: 24.1~26.12 | H31: 36 | I31: 30000 | J31: =I31*12 -> 360000 | K31: =I31*12 -> 360000 | L31: =I31*12 -> 360000 | M31: =SUM(J31:L31) -> 1080000
A32: 28 | B32: 유선 | C32: L3 스위치 | D32: CISCO | E32: N9K-9348GC-FXT | F32: 2 | G32: 24.1~26.12 | H32: 36 | I32: 20000 | J32: =I32*12 -> 240000 | K32: =I32*12 -> 240000 | L32: =I32*12 -> 240000 | M32: =SUM(J32:L32) -> 720000
A33: 29 | B33: 유선 | C33: L3 스위치 | D33: CISCO | E33: N9K-C93180YC-EX | F33: 44 | G33: 24.1~26.12 | H33: 36 | I33: 880000 | J33: =I33*12 -> 10560000 | K33: =I33*12 -> 10560000 | L33: =I33*12 -> 10560000 | M33: =SUM(J33:L33) -> 31680000
... A35: 31 | B35: 유선 | C35: L3 스위치 | D35: CISCO | E35: WS-C3650-24TD-E | F35: 6 | G35: 24.1~26.12 | H35: 36 | I35: 70000 | J35: =I35*12 -> 840000 | K35: =I35*12 -> 840000 | L35: =I35*12 -> 840000 | M35: =SUM(J35:L35) -> 2520000
A36: 32 | B36: 유선 | C36: L3 스위치 | D36: CISCO (신규) | E36: N9K-C93180YC-FX | F36: 2 | G36: 24.2~26.12 | H36: 35 | I36: 40000 | J36: =I36*11 -> 440000 | K36: =I36*12 -> 480000 | L36: =I36*12 -> 480000 | M36: =SUM(J36:L36) -> 1400000
A37: 33 | B37: 유선 | C37: L4 스위치 | D37: RADWARE | E37: Alteon 5208-6G | F37: 52 | G37: 24.1~26.12 | H37: 36 | I37: 6770000 | J37: =I37*12 -> 81240000 | K37: =I37*12 -> 81240000 | L37: =I37*12 -> 81240000 | M37: =SUM(J37:L37) -> 243720000
A38: 34 | B38: 유선 | C38: L4 스위치 | D38: RADWARE (신규) | E38: Alteon 5424-6G | F38: 2 | G38: 24.2~26.12 | H38: 35 | I38: 600000 | J38: =I38*11 -> 6600000 | K38: =I38*12 -> 7200000 | L38: =I38*12 -> 7200000 | M38: =SUM(J38:L38) -> 21000000
A39: 35 | B39: 유선 | C39: PoE 스위치 | D39: CISCO | E39: C2960X-24PS-L | F39: 16 | G39: 24.1~26.12 | H39: 36 | I39: 50000 | J39: =I39*12 -> 600000 | K39: =I39*12 -> 600000 | L39: =I39*12 -> 600000 | M39: =SUM(J39:L39) -> 1800000
A40: 36 | B40: 유선 | C40: PoE 스위치 | D40: CISCO | E40: C3560CX-12PD-S | F40: 40 | G40: 24.1~26.12 | H40: 36 | I40: 480000 | J40: =I40*12 -> 5760000 | K40: =I40*12 -> 5760000 | L40: =I40*12 -> 5760000 | M40: =SUM(J40:L40) -> 17280000
A41: 37 | B41: 유선 | C41: PoE 스위치 | D41: CISCO | E41: C9200L-24P-4G-E | F41: 15 | G41: 24.1~26.12 | H41: 36 | I41: 300000 | J41: =I41*12 -> 3600000 | K41: =I41*12 -> 3600000 | L41: =I41*12 -> 3600000 | M41: =SUM(J41:L41) -> 10800000
A42: 38 | B42: 유선 | C42: PoE 스위치 | D42: CISCO | E42: C9200L-48P-4G-E | F42: 79 | G42: 24.1~26.12 | H42: 36 | I42: 790000 | J42: =I42*12 -> 9480000 | K42: =I42*12 -> 9480000 | L42: =I42*12 -> 9480000 | M42: =SUM(J42:L42) -> 28440000
A43: 39 | B43: 유선 | C43: PoE 스위치 | D43: CISCO | E43: C9200L-48P-4X-E | F43: 1 | G43: 24.1~26.12 | H43: 36 | I43: 10000 | J43: =I43*12 -> 120000 | K43: =I43*12 -> 120000 | L43: =I43*12 -> 120000 | M43: =SUM(J43:L43) -> 360000
...
